[I 200624 05:47:59 main:103] COMMAND: ping, GUILD: bot test CHANNEL: bot-err
[E 200624 05:47:59 main:104] Exception occurred in `ping` in <#725264841018703903>Traceback (most recent call last):
      File "/home/ridley/.local/lib/python3.8/site-packages/discord/ext/commands/bot.py", line 892, in invoke
        await ctx.command.invoke(ctx)
      File "/home/ridley/.local/lib/python3.8/site-packages/discord/ext/commands/core.py", line 797, in invoke
        await injected(*ctx.args, **ctx.kwargs)
      File "/home/ridley/.local/lib/python3.8/site-packages/discord/ext/commands/core.py", line 83, in wrapped
        ret = await coro(*args, **kwargs)
      File "/home/ridley/Untitled-Discord-Bot/addons/misc.py", line 38, in ping
        raise commands.CommandError(message="oi fuck you")
    discord.ext.commands.errors.CommandError: oi fuck you
    NoneType: None
[I 200624 14:10:12 main:103] COMMAND: pull, GUILD: bot test CHANNEL: bot-err
[E 200624 14:10:12 main:104] Exception occurred in `pull` in <#725264841018703903>Traceback (most recent call last):
      File "/home/ridley/.local/lib/python3.8/site-packages/discord/ext/commands/core.py", line 83, in wrapped
        ret = await coro(*args, **kwargs)
      File "/home/ridley/Untitled-Discord-Bot/addons/botowner.py", line 218, in pull
        await self.restart(ctx)
    TypeError: edit() takes 1 positional argument but 2 were given
    
    The above exception was the direct cause of the following exception:
    
    Traceback (most recent call last):
      File "/home/ridley/.local/lib/python3.8/site-packages/discord/ext/commands/bot.py", line 892, in invoke
        await ctx.command.invoke(ctx)
      File "/home/ridley/.local/lib/python3.8/site-packages/discord/ext/commands/core.py", line 797, in invoke
        await injected(*ctx.args, **ctx.kwargs)
      File "/home/ridley/.local/lib/python3.8/site-packages/discord/ext/commands/core.py", line 92, in wrapped
        raise CommandInvokeError(exc) from exc
    discord.ext.commands.errors.CommandInvokeError: Command raised an exception: TypeError: edit() takes 1 positional argument but 2 were given
    NoneType: None
[I 200624 14:16:52 main:103] COMMAND: pull, GUILD: at everyone testing CHANNEL: shhh
[E 200624 14:16:52 main:104] Exception occurred in `pull` in <#725410448882532402>Traceback (most recent call last):
      File "/home/ridley/.local/lib/python3.8/site-packages/discord/ext/commands/core.py", line 83, in wrapped
        ret = await coro(*args, **kwargs)
      File "/home/ridley/Untitled-Discord-Bot/addons/botowner.py", line 217, in pull
        await msg.edit("Restarting....")
    TypeError: edit() takes 1 positional argument but 2 were given
    
    The above exception was the direct cause of the following exception:
    
    Traceback (most recent call last):
      File "/home/ridley/.local/lib/python3.8/site-packages/discord/ext/commands/bot.py", line 892, in invoke
        await ctx.command.invoke(ctx)
      File "/home/ridley/.local/lib/python3.8/site-packages/discord/ext/commands/core.py", line 797, in invoke
        await injected(*ctx.args, **ctx.kwargs)
      File "/home/ridley/.local/lib/python3.8/site-packages/discord/ext/commands/core.py", line 92, in wrapped
        raise CommandInvokeError(exc) from exc
    discord.ext.commands.errors.CommandInvokeError: Command raised an exception: TypeError: edit() takes 1 positional argument but 2 were given
    NoneType: None
[I 200624 14:18:05 main:103] COMMAND: pull, GUILD: at everyone testing CHANNEL: shhh
[E 200624 14:18:05 main:104] Exception occurred in `pull` in <#725410448882532402>Traceback (most recent call last):
      File "/home/ridley/.local/lib/python3.8/site-packages/discord/ext/commands/core.py", line 83, in wrapped
        ret = await coro(*args, **kwargs)
      File "/home/ridley/Untitled-Discord-Bot/addons/botowner.py", line 217, in pull
        await msg.edit("Restarting....")
    NameError: name 'msg' is not defined
    
    The above exception was the direct cause of the following exception:
    
    Traceback (most recent call last):
      File "/home/ridley/.local/lib/python3.8/site-packages/discord/ext/commands/bot.py", line 892, in invoke
        await ctx.command.invoke(ctx)
      File "/home/ridley/.local/lib/python3.8/site-packages/discord/ext/commands/core.py", line 797, in invoke
        await injected(*ctx.args, **ctx.kwargs)
      File "/home/ridley/.local/lib/python3.8/site-packages/discord/ext/commands/core.py", line 92, in wrapped
        raise CommandInvokeError(exc) from exc
    discord.ext.commands.errors.CommandInvokeError: Command raised an exception: NameError: name 'msg' is not defined
    NoneType: None
[I 200625 01:08:19 main:103] COMMAND: jishaku, GUILD: bot test CHANNEL: unique-name
[E 200625 01:08:19 main:104] Exception occurred in `jishaku` in <#656294266867548163>Traceback (most recent call last):
      File "/home/ridley/.local/lib/python3.8/site-packages/discord/ext/commands/bot.py", line 892, in invoke
        await ctx.command.invoke(ctx)
      File "/home/ridley/.local/lib/python3.8/site-packages/discord/ext/commands/core.py", line 1239, in invoke
        await super().invoke(ctx)
      File "/home/ridley/.local/lib/python3.8/site-packages/discord/ext/commands/core.py", line 790, in invoke
        await self.prepare(ctx)
      File "/home/ridley/.local/lib/python3.8/site-packages/discord/ext/commands/core.py", line 751, in prepare
        await self._parse_arguments(ctx)
      File "/home/ridley/.local/lib/python3.8/site-packages/discord/ext/commands/core.py", line 691, in _parse_arguments
        raise TooManyArguments('Too many arguments passed to ' + self.qualified_name)
    discord.ext.commands.errors.TooManyArguments: Too many arguments passed to jishaku
    NoneType: None
[I 200626 15:41:33 main:103] COMMAND: add, GUILD: █▀█ █▄█ ▀█▀ CHANNEL: bot-commands
[E 200626 15:41:33 main:104] Exception occurred in `account add` in <#420437130448470017>Traceback (most recent call last):
      File "/home/ridley/.local/lib/python3.8/site-packages/discord/ext/commands/core.py", line 83, in wrapped
        ret = await coro(*args, **kwargs)
      File "/home/ridley/Untitled-Discord-Bot/cogs/accountinfo.py", line 26, in add
        if accdata[3].isdigit() and accdata[7].isdgit():
    AttributeError: 'str' object has no attribute 'isdgit'
    
    The above exception was the direct cause of the following exception:
    
    Traceback (most recent call last):
      File "/home/ridley/.local/lib/python3.8/site-packages/discord/ext/commands/bot.py", line 892, in invoke
        await ctx.command.invoke(ctx)
      File "/home/ridley/.local/lib/python3.8/site-packages/discord/ext/commands/core.py", line 1234, in invoke
        await ctx.invoked_subcommand.invoke(ctx)
      File "/home/ridley/.local/lib/python3.8/site-packages/discord/ext/commands/core.py", line 797, in invoke
        await injected(*ctx.args, **ctx.kwargs)
      File "/home/ridley/.local/lib/python3.8/site-packages/discord/ext/commands/core.py", line 92, in wrapped
        raise CommandInvokeError(exc) from exc
    discord.ext.commands.errors.CommandInvokeError: Command raised an exception: AttributeError: 'str' object has no attribute 'isdgit'
    NoneType: None
[I 200626 16:10:03 main:103] COMMAND: exit, GUILD: █▀█ █▄█ ▀█▀ CHANNEL: bot-dev
[E 200626 16:10:03 main:104] Exception occurred in `exit` in <#423212406626582530>Traceback (most recent call last):
      File "/home/ridley/.local/lib/python3.8/site-packages/discord/ext/commands/core.py", line 83, in wrapped
        ret = await coro(*args, **kwargs)
      File "/home/ridley/Untitled-Discord-Bot/addons/botowner.py", line 171, in exit
        signal.signal(signal.SIGTERM, self.bot.logout())
      File "/usr/lib/python3.8/signal.py", line 47, in signal
        handler = _signal.signal(_enum_to_int(signalnum), _enum_to_int(handler))
    TypeError: signal handler must be signal.SIG_IGN, signal.SIG_DFL, or a callable object
    
    The above exception was the direct cause of the following exception:
    
    Traceback (most recent call last):
      File "/home/ridley/.local/lib/python3.8/site-packages/discord/ext/commands/bot.py", line 892, in invoke
        await ctx.command.invoke(ctx)
      File "/home/ridley/.local/lib/python3.8/site-packages/discord/ext/commands/core.py", line 797, in invoke
        await injected(*ctx.args, **ctx.kwargs)
      File "/home/ridley/.local/lib/python3.8/site-packages/discord/ext/commands/core.py", line 92, in wrapped
        raise CommandInvokeError(exc) from exc
    discord.ext.commands.errors.CommandInvokeError: Command raised an exception: TypeError: signal handler must be signal.SIG_IGN, signal.SIG_DFL, or a callable object
    NoneType: None
[I 200626 21:46:48 main:103] COMMAND: togglerole, GUILD: █▀█ █▄█ ▀█▀ CHANNEL: vc
[E 200626 21:46:48 main:104] Exception occurred in `togglerole` in <#420433547212488705>Traceback (most recent call last):
      File "/home/ridley/.local/lib/python3.8/site-packages/discord/ext/commands/core.py", line 83, in wrapped
        ret = await coro(*args, **kwargs)
      File "/home/ridley/Untitled-Discord-Bot/cogs/toggleroles.py", line 24, in togglerole
        await self.listroles(ctx)
      File "/home/ridley/Untitled-Discord-Bot/cogs/toggleroles.py", line 63, in listroles
        roledata = json.loads(roledata)
      File "/usr/lib/python3.8/json/__init__.py", line 341, in loads
        raise TypeError(f'the JSON object must be str, bytes or bytearray, '
    TypeError: the JSON object must be str, bytes or bytearray, not dict
    
    The above exception was the direct cause of the following exception:
    
    Traceback (most recent call last):
      File "/home/ridley/.local/lib/python3.8/site-packages/discord/ext/commands/bot.py", line 892, in invoke
        await ctx.command.invoke(ctx)
      File "/home/ridley/.local/lib/python3.8/site-packages/discord/ext/commands/core.py", line 797, in invoke
        await injected(*ctx.args, **ctx.kwargs)
      File "/home/ridley/.local/lib/python3.8/site-packages/discord/ext/commands/core.py", line 92, in wrapped
        raise CommandInvokeError(exc) from exc
    discord.ext.commands.errors.CommandInvokeError: Command raised an exception: TypeError: the JSON object must be str, bytes or bytearray, not dict
    NoneType: None
[I 200626 21:51:59 main:103] COMMAND: togglerole, GUILD: █▀█ █▄█ ▀█▀ CHANNEL: bot-dev
[E 200626 21:51:59 main:104] Exception occurred in `togglerole` in <#423212406626582530>Traceback (most recent call last):
      File "/home/ridley/.local/lib/python3.8/site-packages/discord/ext/commands/core.py", line 83, in wrapped
        ret = await coro(*args, **kwargs)
      File "/home/ridley/Untitled-Discord-Bot/cogs/toggleroles.py", line 24, in togglerole
        await self.listroles(ctx)
      File "/home/ridley/Untitled-Discord-Bot/cogs/toggleroles.py", line 63, in listroles
        roledata = json.loads(roledata)
      File "/usr/lib/python3.8/json/__init__.py", line 341, in loads
        raise TypeError(f'the JSON object must be str, bytes or bytearray, '
    TypeError: the JSON object must be str, bytes or bytearray, not dict
    
    The above exception was the direct cause of the following exception:
    
    Traceback (most recent call last):
      File "/home/ridley/.local/lib/python3.8/site-packages/discord/ext/commands/bot.py", line 892, in invoke
        await ctx.command.invoke(ctx)
      File "/home/ridley/.local/lib/python3.8/site-packages/discord/ext/commands/core.py", line 797, in invoke
        await injected(*ctx.args, **ctx.kwargs)
      File "/home/ridley/.local/lib/python3.8/site-packages/discord/ext/commands/core.py", line 92, in wrapped
        raise CommandInvokeError(exc) from exc
    discord.ext.commands.errors.CommandInvokeError: Command raised an exception: TypeError: the JSON object must be str, bytes or bytearray, not dict
    NoneType: None
[I 200626 21:54:34 main:103] COMMAND: togglerole, GUILD: █▀█ █▄█ ▀█▀ CHANNEL: bot-dev
[E 200626 21:54:34 main:104] Exception occurred in `togglerole` in <#423212406626582530>Traceback (most recent call last):
      File "/home/ridley/.local/lib/python3.8/site-packages/discord/ext/commands/core.py", line 83, in wrapped
        ret = await coro(*args, **kwargs)
      File "/home/ridley/Untitled-Discord-Bot/cogs/toggleroles.py", line 24, in togglerole
        await self.listroles(ctx)
      File "/home/ridley/Untitled-Discord-Bot/cogs/toggleroles.py", line 63, in listroles
        roledata = json.loads(roledata)
      File "/usr/lib/python3.8/json/__init__.py", line 341, in loads
        raise TypeError(f'the JSON object must be str, bytes or bytearray, '
    TypeError: the JSON object must be str, bytes or bytearray, not dict
    
    The above exception was the direct cause of the following exception:
    
    Traceback (most recent call last):
      File "/home/ridley/.local/lib/python3.8/site-packages/discord/ext/commands/bot.py", line 892, in invoke
        await ctx.command.invoke(ctx)
      File "/home/ridley/.local/lib/python3.8/site-packages/discord/ext/commands/core.py", line 797, in invoke
        await injected(*ctx.args, **ctx.kwargs)
      File "/home/ridley/.local/lib/python3.8/site-packages/discord/ext/commands/core.py", line 92, in wrapped
        raise CommandInvokeError(exc) from exc
    discord.ext.commands.errors.CommandInvokeError: Command raised an exception: TypeError: the JSON object must be str, bytes or bytearray, not dict
    NoneType: None
